[2022-11-05 14:59:12,573] {taskinstance.py:851} INFO - Dependencies all met for <TaskInstance: get_tax_receipts.find_large_receipts 2022-11-04T14:58:46.176951+00:00 [queued]>
[2022-11-05 14:59:12,615] {taskinstance.py:851} INFO - Dependencies all met for <TaskInstance: get_tax_receipts.find_large_receipts 2022-11-04T14:58:46.176951+00:00 [queued]>
[2022-11-05 14:59:12,617] {taskinstance.py:1042} INFO - 
--------------------------------------------------------------------------------
[2022-11-05 14:59:12,618] {taskinstance.py:1043} INFO - Starting attempt 1 of 1
[2022-11-05 14:59:12,620] {taskinstance.py:1044} INFO - 
--------------------------------------------------------------------------------
[2022-11-05 14:59:12,643] {taskinstance.py:1063} INFO - Executing <Task(PythonOperator): find_large_receipts> on 2022-11-04T14:58:46.176951+00:00
[2022-11-05 14:59:12,655] {standard_task_runner.py:52} INFO - Started process 104 to run task
[2022-11-05 14:59:12,667] {standard_task_runner.py:76} INFO - Running: ['airflow', 'tasks', 'run', 'get_tax_receipts', 'find_large_receipts', '2022-11-04T14:58:46.176951+00:00', '--job-id', '41', '--pool', 'default_pool', '--raw', '--subdir', 'DAGS_FOLDER/texas_dags.py', '--cfg-path', '/tmp/tmp7_wii1gc', '--error-file', '/tmp/tmpg_2so28j']
[2022-11-05 14:59:12,669] {standard_task_runner.py:77} INFO - Job 41: Subtask find_large_receipts
[2022-11-05 14:59:12,775] {logging_mixin.py:104} INFO - Running <TaskInstance: get_tax_receipts.find_large_receipts 2022-11-04T14:58:46.176951+00:00 [running]> on host c0f23e4d7a13
[2022-11-05 14:59:12,912] {taskinstance.py:1257} INFO - Exporting the following env vars:
AIRFLOW_CTX_DAG_OWNER=airflow
AIRFLOW_CTX_DAG_ID=get_tax_receipts
AIRFLOW_CTX_TASK_ID=find_large_receipts
AIRFLOW_CTX_EXECUTION_DATE=2022-11-04T14:58:46.176951+00:00
AIRFLOW_CTX_DAG_RUN_ID=scheduled__2022-11-04T14:58:46.176951+00:00
[2022-11-05 14:59:12,929] {taskinstance.py:1455} ERROR - [Errno 2] No such file or directory: './records'
Traceback (most recent call last):
  File "/home/airflow/.local/lib/python3.6/site-packages/airflow/models/taskinstance.py", line 1112, in _run_raw_task
    self._prepare_and_execute_task_with_callbacks(context, task)
  File "/home/airflow/.local/lib/python3.6/site-packages/airflow/models/taskinstance.py", line 1285, in _prepare_and_execute_task_with_callbacks
    result = self._execute_task(context, task_copy)
  File "/home/airflow/.local/lib/python3.6/site-packages/airflow/models/taskinstance.py", line 1315, in _execute_task
    result = task_copy.execute(context=context)
  File "/home/airflow/.local/lib/python3.6/site-packages/airflow/operators/python.py", line 117, in execute
    return_value = self.execute_callable()
  File "/home/airflow/.local/lib/python3.6/site-packages/airflow/operators/python.py", line 128, in execute_callable
    return self.python_callable(*self.op_args, **self.op_kwargs)
  File "/opt/airflow/dags/texas_dags.py", line 20, in find_receipts
    df = pd.read_csv('./records')
  File "/home/airflow/.local/lib/python3.6/site-packages/pandas/io/parsers.py", line 688, in read_csv
    return _read(filepath_or_buffer, kwds)
  File "/home/airflow/.local/lib/python3.6/site-packages/pandas/io/parsers.py", line 454, in _read
    parser = TextFileReader(fp_or_buf, **kwds)
  File "/home/airflow/.local/lib/python3.6/site-packages/pandas/io/parsers.py", line 948, in __init__
    self._make_engine(self.engine)
  File "/home/airflow/.local/lib/python3.6/site-packages/pandas/io/parsers.py", line 1180, in _make_engine
    self._engine = CParserWrapper(self.f, **self.options)
  File "/home/airflow/.local/lib/python3.6/site-packages/pandas/io/parsers.py", line 2010, in __init__
    self._reader = parsers.TextReader(src, **kwds)
  File "pandas/_libs/parsers.pyx", line 382, in pandas._libs.parsers.TextReader.__cinit__
  File "pandas/_libs/parsers.pyx", line 674, in pandas._libs.parsers.TextReader._setup_parser_source
FileNotFoundError: [Errno 2] No such file or directory: './records'
[2022-11-05 14:59:12,961] {taskinstance.py:1503} INFO - Marking task as FAILED. dag_id=get_tax_receipts, task_id=find_large_receipts, execution_date=20221104T145846, start_date=20221105T145912, end_date=20221105T145912
[2022-11-05 14:59:13,080] {local_task_job.py:146} INFO - Task exited with return code 1
